<?xml version="1.0" ?>
<robot name="so_arm" xmlns:xacro="http://ros.org/wiki/xacro">
  <!-- 0 1.570795 3.14159 -->
  <material name="White">
    <color rgba="0.87 0.90 0.87 1.0"/>
  </material>
  <material name="Black">
    <color rgba="0.08 0.08 0.08 1.0"/>
  </material>
  <material name="Gray">
    <color rgba="0.2 0.2 0.21 1.0"/>
  </material>
  <material name="Green">
    <color rgba="0.22 0.32 0.14 1.0"/>
  </material>
  <link name="map"/>
  <joint name="gripper_wrist_joint" type="fixed">
    <origin xyz="0.0 0.0 0"/>
    <parent link="map"/>
    <child link="gripper_wrist_link"/>
  </joint>
  <link name="gripper_wrist_link">
    <visual>
      <origin rpy="0 0 0" xyz="0 0 0"/>
      <geometry>
        <mesh filename="package://so_arm_description/meshes/gripper_wrist.stl" scale="0.001 0.001 0.001"/>
      </geometry>
      <material name="Gray"/>
    </visual>
  </link>
  <joint name="gripper_servo_joint" type="fixed">
    <origin rpy="0 1.570795 1.570795" xyz="0.0455 -0.002 -0.069"/>
    <parent link="gripper_wrist_link"/>
    <child link="gripper_servo_link"/>
  </joint>
  <link name="gripper_servo_link">
    <!-- YYY
    <inertial>
      <mass value="0.055"/>
      <origin xyz="0 0 0"/>
      <inertia ixx="0.000017012" ixy="0.0" ixz="0.0" iyy="0.000013258" iyz="0.0" izz="0.000009483"/>
    </inertial>
    -->
    <visual>
      <origin rpy="0 0 0" xyz=" 0 0 0 "/>
      <geometry>
        <mesh filename="package://so_arm_description/meshes/servo.stl" scale="0.001 0.001 0.001"/>
      </geometry>
      <material name="Black"/>
    </visual>
    <collision>
      <origin rpy="0 0 0" xyz="0.0 0.0 -0.01241"/>
      <geometry>
        <box size="0.02 0.038 0.054"/>
      </geometry>
    </collision>
  </link>
  <gazebo reference="gripper_servo_link">
    <material>Gazebo/Black</material>
    <selfCollide>true</selfCollide>
    <gravity>true</gravity>
  </gazebo>
  <!-- Finger 1 -->
  <joint name="gripper_left_joint" type="prismatic">
    <origin rpy="3.14159 0 0" xyz="0.0265 0.0135 -0.005"/>
    <axis xyz="0 0 1"/>
    <limit effort="30" lower="0.002" upper="0.030" velocity="0.5"/>
    <parent link="gripper_wrist_link"/>
    <child link="gripper_left_finger_link"/>
  </joint>
  <link name="gripper_left_finger_link">
    <visual>
      <origin rpy="0 0 0" xyz="0 0 0"/>
      <geometry>
        <mesh filename="package://so_arm_description/meshes/gripper_finger_left.stl" scale="0.001 0.001 0.001"/>
      </geometry>
      <material name="Gray"/>
    </visual>
  </link>
  <joint name="gripper_left_pad_joint" type="fixed">
    <origin rpy="3.14159 0 1.570795" xyz="-0.002 0.052 -0.002"/>
    <parent link="gripper_left_finger_link"/>
    <child link="gripper_left_pad_link"/>
  </joint>
  <link name="gripper_left_pad_link">
    <visual>
      <origin rpy="0 0 0" xyz="0 0 0"/>
      <geometry>
        <mesh filename="package://so_arm_description/meshes/gripper_finger_pad.stl" scale="0.001 0.001 0.001"/>
      </geometry>
      <material name="Black"/>
    </visual>
  </link>
  <!-- Using Mimic -->
  <!-- gripper 2 joint -->
  <joint name="gripper_right_joint" type="prismatic">
    <origin rpy="0 0 0" xyz="0.0265 0.00 0.002"/>
    <axis xyz="0 0 1"/>
    <limit effort="30" velocity="0.5" lower="0.002" upper="0.030"/>
    <parent link="gripper_wrist_link"/>
    <child link="gripper_right_finger_link"/>
    <mimic joint="gripper_left_joint" multiplier="1"  offset = "0"/>
  </joint>
  <link name="gripper_right_finger_link">
    <visual>
      <origin rpy="0 0 0" xyz="0 0 0"/>
      <geometry>
        <mesh filename="package://so_arm_description/meshes/gripper_finger_right.stl" scale="0.001 0.001 0.001"/>
      </geometry>
      <material name="Gray"/>
    </visual>
  </link>
  <joint name="gripper_right_pad_joint" type="fixed">
    <origin rpy="3.14159 0 1.570795" xyz="-0.002 0.052 -0.002"/>
    <parent link="gripper_right_finger_link"/>
    <child link="gripper_right_pad_link"/>
  </joint>
  <link name="gripper_right_pad_link">
    <visual>
      <origin rpy="0 0 0" xyz="0 0 0"/>
      <geometry>
        <mesh filename="package://so_arm_description/meshes/gripper_finger_pad.stl" scale="0.001 0.001 0.001"/>
      </geometry>
      <material name="Black"/>
    </visual>
  </link>

</robot>
