<?xml version="1.0" ?>
<robot name="so_arm" xmlns:xacro="http://ros.org/wiki/xacro">
  <material name="White">
    <color rgba="0.87 0.90 0.87 1.0"/>
  </material>
  <material name="Black">
    <color rgba="0.08 0.08 0.08 1.0"/>
  </material>
  <material name="Gray">
    <color rgba="0.2 0.2 0.21 1.0"/>
  </material>
  <material name="Green">
    <color rgba="0.22 0.32 0.14 1.0"/>
  </material>
  <link name="robot_base_footprint"/>
  <link name="arm_base_link">
    <visual>
      <origin rpy="0 0 0" xyz="0 0 0"/>
      <geometry>
        <box size="0.30 0.30 0.013"/>
      </geometry>
      <material name="Gray"/>
    </visual>
  </link>
  <joint name="arm_base_joint" type="fixed">
    <origin xyz="0.0 0.0 0.0065"/>
    <parent link="robot_base_footprint"/>
    <child link="arm_base_link"/>
  </joint>
  <joint name="arm_shoulder_pan_servo_joint" type="fixed">
    <origin rpy="-1.570795 0 1.570795" xyz="0 0.01 0.0265"/>
    <parent link="arm_base_link"/>
    <child link="arm_shoulder_pan_servo_link"/>
  </joint>
  <link name="arm_shoulder_pan_servo_link">
    <!--
    <inertial>
      <mass value="0.055"/>
      <origin xyz="0 0 0"/>
      <inertia ixx="0.000017012" ixy="0.0" ixz="0.0" iyy="0.000013258" iyz="0.0" izz="0.000009483"/>
    </inertial>
    -->
    <visual>
      <origin rpy="0 0 0" xyz=" 0 0 0 "/>
      <geometry>
        <mesh filename="package://so_arm_description/meshes/ax12_box.stl" scale="0.001 0.001 0.001"/>
      </geometry>
      <material name="Black"/>
    </visual>
    <!--
    <collision>
      <origin rpy="0 0 0" xyz="0.0 0.0 -0.01241"/>
      <geometry>
        <box size="0.025 0.038 0.04762"/>
      </geometry>
    </collision>
    -->
  </link>
  <joint name="shoulder_plate_rotate_joint" type="revolute">
    <origin rpy="-1.570795 0 0" xyz="-0.01 -0.026 0"/>
    <axis xyz="0 0 1"/>
    <!-- limit effort="30" lower="-2.2" upper="2.16" velocity="1.571"/ -->
    <limit effort="100" lower="-2.2" upper="2.16" velocity="4.571"/>
    <dynamics friction="0.13"/>
    <parent link="arm_shoulder_pan_servo_link"/>
    <child link="shoulder_plate_link"/>
  </joint>
  <link name="shoulder_plate_link">
    <visual>
      <origin rpy="0 0 0" xyz="0 0 0"/>
      <geometry>
        <cylinder radius="0.06" length="0.003"/>
      </geometry>
      <material name="Grey"/>
    </visual>
  </link>
  <joint name="shoulder_plate_joint" type="fixed">
    <origin rpy="-1.570795 0 0" xyz="0.012 0 -0.0015"/>
    <parent link="shoulder_plate_link"/>
    <child link="shoulder_pan_link"/>
  </joint>
  <link name="shoulder_pan_link">
    <!--
    <inertial>
      <mass value="0.008"/>
      <origin xyz="0 0 0"/>
      <inertia ixx="0.000001" ixy="0.0" ixz="0.0" iyy="0.000001" iyz="0.0" izz="0.000001"/>
    </inertial>
    -->
    <visual>
      <origin rpy="0 0 0" xyz=" 0 0 0 "/>
      <geometry>
        <mesh filename="package://so_arm_description/meshes/F3.stl" scale="0.001 0.001 0.001"/>
      </geometry>
      <material name="Gray"/>
    </visual>
    <!--
    <collision>
      <origin rpy="0 0 0" xyz="0.0 0.0 -0.0045"/>
      <geometry>
        <box size="0.025 0.038 0.009"/>
      </geometry>
    </collision>
    -->
  </link>
  <gazebo reference="shoulder_pan_link">
    <material>Gazebo/Gray</material>
    <selfCollide>true</selfCollide>
    <gravity>true</gravity>
  </gazebo>
  <joint name="shoulder_lift_servo_joint" type="fixed">
    <origin rpy="-1.570795 0 0" xyz="-0.0025 0.0195 0"/>
    <parent link="shoulder_pan_link"/>
    <child link="shoulder_lift_servo_link"/>
  </joint>
  <link name="shoulder_lift_servo_link">
    <!--
    <inertial>
      <mass value="0.055"/>
      <origin xyz="0 0 0"/>
      <inertia ixx="0.000017012" ixy="0.0" ixz="0.0" iyy="0.000013258" iyz="0.0" izz="0.000009483"/>
    </inertial>
    -->
    <visual>
      <origin rpy="0 0 0" xyz=" 0 0 0 "/>
      <geometry>
        <mesh filename="package://so_arm_description/meshes/ax12_box.stl" scale="0.001 0.001 0.001"/>
      </geometry>
      <material name="Black"/>
    </visual>
    <!--
    <collision>
      <origin rpy="0 0 0" xyz="0.0 0.0 -0.01241"/>
      <geometry>
        <box size="0.025 0.038 0.04762"/>
      </geometry>
    </collision>
    -->
  </link>
  <gazebo reference="shoulder_lift_servo_link">
    <material>Gazebo/Black</material>
    <selfCollide>true</selfCollide>
    <gravity>true</gravity>
  </gazebo>
  <joint name="shoulder_lift_joint" type="revolute">
    <origin rpy="1.570795 1.570795 0" xyz="-0.012 0 0"/>
    <axis xyz="0 0 1"/>
    <limit effort="100" lower="-2.0" upper="0.05" velocity="4.571"/>
    <dynamics friction="0.13"/>
    <parent link="shoulder_lift_servo_link"/>
    <child link="shoulder_lift_link"/>
  </joint>
  <link name="shoulder_lift_link">
    <!--
    <inertial>
      <mass value="0.016"/>
      <origin xyz="0 0 0"/>
      <inertia ixx="0.000001" ixy="0.0" ixz="0.0" iyy="0.000001" iyz="0.0" izz="0.000001"/>
    </inertial>
    -->
    <visual>
      <origin rpy="0 0 0" xyz=" 0 0 0 "/>
      <geometry>
        <mesh filename="package://so_arm_description/meshes/F4.stl" scale="0.001 0.001 0.001"/>
      </geometry>
      <material name="Gray"/>
    </visual>
    <!--
    <collision>
      <origin rpy="0 0 0" xyz="0.0 0.0 0.0215"/>
      <geometry>
        <box size="0.028 0.0485 0.065"/>
      </geometry>
    </collision>
    -->
  </link>
  <gazebo reference="shoulder_lift_link">
    <material>Gazebo/Gray</material>
    <selfCollide>true</selfCollide>
    <gravity>true</gravity>
  </gazebo>
  <joint name="upper_arm_joint" type="fixed">
    <origin rpy="1.570795 0 0" xyz="0 -0.1565 0"/>
    <parent link="shoulder_lift_link"/>
    <child link="upper_arm_link"/>
  </joint>
  <link name="upper_arm_link">
    <!-- YYY
    <inertial>
      <mass value="0.004"/>
      <origin xyz="0 0 0"/>
      <inertia ixx="0.000001" ixy="0.0" ixz="0.0" iyy="0.000001" iyz="0.0" izz="0.000001"/>
    </inertial>
    -->
    <visual>
      <origin rpy="0 0 0" xyz=" 0 0 0 "/>
      <geometry>
        <box size="0.028 0.038 0.205"/>
      </geometry>
      <material name="Gray"/>
    </visual>
    <!--
    <collision>
      <origin rpy="0 0 0" xyz="0.0 0.0 0.0"/>
      <geometry>
        <box size="0.028 0.038 0.205"/>
      </geometry>
    </collision>
    -->
  </link>
  <gazebo reference="upper_arm_link">
    <material>Gazebo/Gray</material>
    <selfCollide>true</selfCollide>
    <gravity>true</gravity>
  </gazebo>
  <!-- elbow joint -->
  <joint name="elbow_flex_servo_joint" type="fixed">
    <origin rpy="0 1.570795 3.14159" xyz="0 0 0.129"/>
    <parent link="upper_arm_link"/>
    <child link="elbow_flex_servo_link"/>
  </joint>
  <link name="elbow_flex_servo_link">
    <!--
    <inertial>
      <mass value="0.055"/>
      <origin xyz="0 0 0"/>
      <inertia ixx="0.000017012" ixy="0.0" ixz="0.0" iyy="0.000013258" iyz="0.0" izz="0.000009483"/>
    </inertial>
    -->
    <visual>
      <origin rpy="0 0 0" xyz=" 0 0 0 "/>
      <geometry>
        <mesh filename="package://so_arm_description/meshes/ax12_box.stl" scale="0.001 0.001 0.001"/>
      </geometry>
      <material name="Black"/>
    </visual>
    <!--
    <collision>
      <origin rpy="0 0 0" xyz="0.0 0.0 -0.01241"/>
      <geometry>
        <box size="0.025 0.038 0.04762"/>
      </geometry>
    </collision>
    -->
  </link>
  <gazebo reference="elbow_flex_servo_link">
    <material>Gazebo/Black</material>
    <selfCollide>true</selfCollide>
    <gravity>true</gravity>
  </gazebo>
  <joint name="elbow_flex_joint" type="revolute">
    <origin rpy="1.570795 1.570795 0" xyz="-0.012 0 0"/>
    <axis xyz="0 0 1"/>
    <limit effort="100" lower="0" upper="2.5" velocity="4.571"/>
    <dynamics friction="0.13"/>
    <parent link="elbow_flex_servo_link"/>
    <child link="elbow_flex_link"/>
  </joint>
  <link name="elbow_flex_link">
    <!--
    <inertial>
      <mass value="0.016"/>
      <origin xyz="0 0 0"/>
      <inertia ixx="0.000001" ixy="0.0" ixz="0.0" iyy="0.000001" iyz="0.0" izz="0.000001"/>
    </inertial>
    -->
    <visual>
      <origin rpy="0 0 0" xyz=" 0 0 0 "/>
      <geometry>
        <mesh filename="package://so_arm_description/meshes/F4.stl" scale="0.001 0.001 0.001"/>
      </geometry>
      <material name="Gray"/>
    </visual>
    <!--
    <collision>
      <origin rpy="0 0 0" xyz="0.0 0.0 0.0215"/>
      <geometry>
        <box size="0.028 0.0485 0.065"/>
      </geometry>
    </collision>
    -->
  </link>
  <gazebo reference="elbow_flex_link">
    <material>Gazebo/Gray</material>
    <selfCollide>true</selfCollide>
    <gravity>true</gravity>
  </gazebo>
  <joint name="lower_arm_joint" type="fixed">
    <origin rpy="1.570795 0 0" xyz="0 -0.158 0"/>
    <parent link="elbow_flex_link"/>
    <child link="lower_arm_link"/>
  </joint>
  <link name="lower_arm_link">
    <!-- YYY
    <inertial>
      <mass value="0.004"/>
      <origin xyz="0 0 0"/>
      <inertia ixx="0.000001" ixy="0.0" ixz="0.0" iyy="0.000001" iyz="0.0" izz="0.000001"/>
    </inertial>
    -->
    <visual>
      <origin rpy="0 0 0" xyz=" 0 0 0 "/>
      <geometry>
        <box size="0.028 0.038 0.208"/>
      </geometry>
      <material name="Gray"/>
    </visual>
    <!--
    <collision>
      <origin rpy="0 0 0" xyz="0.0 0.0 0.0"/>
      <geometry>
        <box size="0.028 0.038 0.208"/>
      </geometry>
    </collision>
    -->
  </link>
  <gazebo reference="lower_arm_link">
    <material>Gazebo/Gray</material>
    <selfCollide>true</selfCollide>
    <gravity>true</gravity>
  </gazebo>
  <joint name="wrist_flex_servo_joint" type="fixed">
    <origin rpy="0 1.570795 3.14159" xyz="0 0 0.1305"/>
    <parent link="lower_arm_link"/>
    <child link="wrist_flex_servo_link"/>
  </joint>
  <link name="wrist_flex_servo_link">
    <!--
    <inertial>
      <mass value="0.055"/>
      <origin xyz="0 0 0"/>
      <inertia ixx="0.000017012" ixy="0.0" ixz="0.0" iyy="0.000013258" iyz="0.0" izz="0.000009483"/>
    </inertial>
    -->
    <visual>
      <origin rpy="0 0 0" xyz=" 0 0 0 "/>
      <geometry>
        <mesh filename="package://so_arm_description/meshes/ax12_box.stl" scale="0.001 0.001 0.001"/>
      </geometry>
      <material name="Black"/>
    </visual>
    <!--
    <collision>
      <origin rpy="0 0 0" xyz="0.0 0.0 -0.01241"/>
      <geometry>
        <box size="0.025 0.038 0.04762"/>
      </geometry>
    </collision>
    -->
  </link>
  <gazebo reference="wrist_flex_servo_link">
    <material>Gazebo/Black</material>
    <selfCollide>true</selfCollide>
    <gravity>true</gravity>
  </gazebo>
  <joint name="wrist_flex_joint" type="revolute">
    <origin rpy="1.570795 1.570795 0" xyz="-0.012 0 0"/>
    <axis xyz="0 0 1"/>
    <limit effort="100" lower="-1.65" upper="1.65" velocity="4.571"/>
    <dynamics friction="0.13"/>
    <parent link="wrist_flex_servo_link"/>
    <child link="wrist_flex_link"/>
  </joint>
  <link name="wrist_flex_link">
    <!--
    <inertial>
      <mass value="0.010"/>
      <origin xyz="0 0 0"/>
      <inertia ixx="0.000001" ixy="0.0" ixz="0.0" iyy="0.000001" iyz="0.0" izz="0.000001"/>
    </inertial>
    -->
    <visual>
      <origin rpy="0 0 0" xyz=" 0 0 0 "/>
      <geometry>
        <mesh filename="package://so_arm_description/meshes/F2.stl" scale="0.001 0.001 0.001"/>
      </geometry>
      <material name="Gray"/>
    </visual>
    <!--
    <collision>
      <origin rpy="0 0 0" xyz="0.0 0.0 0.00775"/>
      <geometry>
        <box size="0.025 0.0485 0.0375"/>
      </geometry>
    </collision>
    -->
  </link>
  <gazebo reference="wrist_flex_link">
    <material>Gazebo/Gray</material>
    <selfCollide>true</selfCollide>
    <gravity>true</gravity>
  </gazebo>
  <joint name="wrist_pan_servo_joint" type="fixed">
    <origin rpy="0 1.570795 0" xyz="0 -0.046 -0.012"/>
    <parent link="wrist_flex_link"/>
    <child link="wrist_pan_servo_link"/>
  </joint>
  <link name="wrist_pan_servo_link">
    <!--
    <inertial>
      <mass value="0.055"/>
      <origin xyz="0 0 0"/>
      <inertia ixx="0.000017012" ixy="0.0" ixz="0.0" iyy="0.000013258" iyz="0.0" izz="0.000009483"/>
    </inertial>
    -->
    <visual>
      <origin rpy="0 0 0" xyz=" 0 0 0 "/>
      <geometry>
        <mesh filename="package://so_arm_description/meshes/ax12_box.stl" scale="0.001 0.001 0.001"/>
      </geometry>
      <material name="Black"/>
    </visual>
    <!--
    <collision>
      <origin rpy="0 0 0" xyz="0.0 0.0 -0.01241"/>
      <geometry>
        <box size="0.025 0.038 0.04762"/>
      </geometry>
    </collision>
    -->
  </link>
  <gazebo reference="wrist_pan_servo_link">
    <material>Gazebo/Black</material>
    <selfCollide>true</selfCollide>
    <gravity>true</gravity>
  </gazebo>
  <joint name="wrist_pan_joint" type="revolute">
    <origin rpy="1.570795 1.570795 0" xyz="-0.012 -0.022 0"/>
    <axis xyz="0 0 1"/>
    <limit effort="100" lower="-2.2" upper="2.2" velocity="4.571"/>
    <dynamics friction="0.13"/>
    <parent link="wrist_pan_servo_link"/>
    <child link="wrist_pan_link"/>
  </joint>
  <link name="wrist_pan_link">
    <!-- YYY
    <inertial>
      <mass value="0.004"/>
      <origin xyz="0 0 0"/>
      <inertia ixx="0.000001" ixy="0.0" ixz="0.0" iyy="0.000001" iyz="0.0" izz="0.000001"/>
    </inertial>
    -->
    <visual>
      <origin rpy="0 0 0" xyz=" 0 0 0 "/>
      <geometry>
        <box size="0.028 0.065 0.003"/>
      </geometry>
      <material name="Gray"/>
    </visual>
    <!--
    <collision>
      <origin rpy="0 0 0" xyz="0.0 0.0 0.0"/>
      <geometry>
        <box size="0.028 0.065 0.003"/>
      </geometry>
    </collision>
    -->
  </link>

  <!-- 0 1.570795 3.14159 -->
  <joint name="gripper_wrist_joint" type="fixed">
    <origin rpy="1.570795 -1.570795 0" xyz="0.007 0 0.003"/>
    <parent link="wrist_pan_link"/>
    <child link="gripper_wrist_link"/>
  </joint>
  <link name="gripper_wrist_link">
    <visual>
      <origin rpy="0 0 0" xyz="0 0 0"/>
      <geometry>
        <mesh filename="package://so_arm_description/meshes/gripper_wrist.stl" scale="0.001 0.001 0.001"/>
      </geometry>
      <material name="Gray"/>
    </visual>
  </link>
  <joint name="gripper_servo_joint" type="fixed">
    <origin rpy="0 1.570795 1.570795" xyz="0.0455 -0.002 -0.069"/>
    <parent link="gripper_wrist_link"/>
    <child link="gripper_servo_link"/>
  </joint>
  <link name="gripper_servo_link">
    <!-- YYY
    <inertial>
      <mass value="0.055"/>
      <origin xyz="0 0 0"/>
      <inertia ixx="0.000017012" ixy="0.0" ixz="0.0" iyy="0.000013258" iyz="0.0" izz="0.000009483"/>
    </inertial>
    -->
    <visual>
      <origin rpy="0 0 0" xyz=" 0 0 0 "/>
      <geometry>
        <mesh filename="package://so_arm_description/meshes/servo.stl" scale="0.001 0.001 0.001"/>
      </geometry>
      <material name="Black"/>
    </visual>
    <!--
    <collision>
      <origin rpy="0 0 0" xyz="0.0 0.0 -0.01241"/>
      <geometry>
        <box size="0.02 0.038 0.054"/>
      </geometry>
    </collision>
    -->
  </link>
  <gazebo reference="gripper_servo_link">
    <material>Gazebo/Black</material>
    <selfCollide>true</selfCollide>
    <gravity>true</gravity>
  </gazebo>
  <!-- Finger 1 -->
  <joint name="gripper_left_joint" type="prismatic">
    <origin rpy="3.14159 0 0" xyz="0.0265 0.0135 -0.005"/>
    <axis xyz="0 0 1"/>
    <limit effort="100" lower="0.002" upper="0.030" velocity="5"/>
    <parent link="gripper_wrist_link"/>
    <child link="gripper_left_finger_link"/>
  </joint>
  <link name="gripper_left_finger_link">
    <visual>
      <origin rpy="0 0 0" xyz="0 0 0"/>
      <geometry>
        <mesh filename="package://so_arm_description/meshes/gripper_finger_left.stl" scale="0.001 0.001 0.001"/>
      </geometry>
      <material name="Gray"/>
    </visual>
  </link>
  <joint name="gripper_left_pad_joint" type="fixed">
    <origin rpy="3.14159 0 1.570795" xyz="-0.002 0.052 -0.002"/>
    <parent link="gripper_left_finger_link"/>
    <child link="gripper_left_pad_link"/>
  </joint>
  <link name="gripper_left_pad_link">
    <visual>
      <origin rpy="0 0 0" xyz="0 0 0"/>
      <geometry>
        <mesh filename="package://so_arm_description/meshes/gripper_finger_pad.stl" scale="0.001 0.001 0.001"/>
      </geometry>
      <material name="Black"/>
    </visual>
  </link>
  <!-- Using Mimic -->
  <!-- gripper 2 joint -->
  <joint name="gripper_right_joint" type="prismatic">
    <origin rpy="0 0 0" xyz="0.0265 0.00 0.002"/>
    <axis xyz="0 0 1"/>
    <limit effort="100" velocity="5" lower="0.002" upper="0.030"/>
    <parent link="gripper_wrist_link"/>
    <child link="gripper_right_finger_link"/>
    <mimic joint="gripper_left_joint" multiplier="1"  offset = "0"/>
  </joint>
  <link name="gripper_right_finger_link">
    <visual>
      <origin rpy="0 0 0" xyz="0 0 0"/>
      <geometry>
        <mesh filename="package://so_arm_description/meshes/gripper_finger_right.stl" scale="0.001 0.001 0.001"/>
      </geometry>
      <material name="Gray"/>
    </visual>
  </link>
  <joint name="gripper_right_pad_joint" type="fixed">
    <origin rpy="3.14159 0 1.570795" xyz="-0.002 0.052 -0.002"/>
    <parent link="gripper_right_finger_link"/>
    <child link="gripper_right_pad_link"/>
  </joint>
  <link name="gripper_right_pad_link">
    <visual>
      <origin rpy="0 0 0" xyz="0 0 0"/>
      <geometry>
        <mesh filename="package://so_arm_description/meshes/gripper_finger_pad.stl" scale="0.001 0.001 0.001"/>
      </geometry>
      <material name="Black"/>
    </visual>
  </link>

</robot>

